<?xml version="1.0" encoding="UTF-8"?>
<testng-results ignored="0" total="4" passed="1" failed="3" skipped="0">
  <reporter-output>
  </reporter-output>
  <suite started-at="2020-08-24T16:53:39 ICT" name="Suite" finished-at="2020-08-24T16:53:55 ICT" duration-ms="16285">
    <groups>
    </groups>
    <test started-at="2020-08-24T16:53:39 ICT" name="TestBanking App" finished-at="2020-08-24T16:53:55 ICT" duration-ms="16285">
      <class name="com.inetbanking.testCases.TC_LoginTest_001">
        <test-method is-config="true" signature="initalize()[pri:0, instance:com.inetbanking.testCases.TC_LoginTest_001@1c98290c]" started-at="2020-08-24T16:53:39 ICT" name="initalize" finished-at="2020-08-24T16:53:45 ICT" duration-ms="6044" status="PASS">
          <reporter-output>
          </reporter-output>
        </test-method> <!-- initalize -->
        <test-method is-config="true" signature="setup()[pri:0, instance:com.inetbanking.testCases.TC_LoginTest_001@1c98290c]" started-at="2020-08-24T16:53:45 ICT" name="setup" finished-at="2020-08-24T16:53:49 ICT" duration-ms="4105" status="PASS">
          <reporter-output>
          </reporter-output>
        </test-method> <!-- setup -->
        <test-method signature="LoginTest(java.lang.String, java.lang.String)[pri:0, instance:com.inetbanking.testCases.TC_LoginTest_001@1c98290c]" started-at="2020-08-24T16:53:49 ICT" name="LoginTest" data-provider="getData" finished-at="2020-08-24T16:53:51 ICT" duration-ms="2019" status="FAIL">
          <params>
            <param index="0">
              <value>
                <![CDATA[sarah@email.com]]>
              </value>
            </param>
            <param index="1">
              <value>
                <![CDATA[seleniumjava321]]>
              </value>
            </param>
          </params>
          <exception class="java.lang.AssertionError">
            <message>
              <![CDATA[expected [Login | Salesforce3623] but found [Login | Salesforce]]]>
            </message>
            <full-stacktrace>
              <![CDATA[java.lang.AssertionError: expected [Login | Salesforce3623] but found [Login | Salesforce]
at org.testng.Assert.fail(Assert.java:97)
at org.testng.Assert.assertEqualsImpl(Assert.java:136)
at org.testng.Assert.assertEquals(Assert.java:118)
at org.testng.Assert.assertEquals(Assert.java:575)
at org.testng.Assert.assertEquals(Assert.java:585)
at com.inetbanking.testCases.TC_LoginTest_001.LoginTest(TC_LoginTest_001.java:32)
at java.base/jdk.internal.reflect.NativeMethodAccessorImpl.invoke0(Native Method)
at java.base/jdk.internal.reflect.NativeMethodAccessorImpl.invoke(NativeMethodAccessorImpl.java:62)
at java.base/jdk.internal.reflect.DelegatingMethodAccessorImpl.invoke(DelegatingMethodAccessorImpl.java:43)
at java.base/java.lang.reflect.Method.invoke(Method.java:566)
at org.testng.internal.MethodInvocationHelper.invokeMethod(MethodInvocationHelper.java:135)
at org.testng.internal.TestInvoker.invokeMethod(TestInvoker.java:598)
at org.testng.internal.TestInvoker.invokeTestMethod(TestInvoker.java:174)
at org.testng.internal.MethodRunner.runInSequence(MethodRunner.java:46)
at org.testng.internal.TestInvoker$MethodInvocationAgent.invoke(TestInvoker.java:821)
at org.testng.internal.TestInvoker.invokeTestMethods(TestInvoker.java:147)
at org.testng.internal.TestMethodWorker.invokeTestMethods(TestMethodWorker.java:146)
at org.testng.internal.TestMethodWorker.run(TestMethodWorker.java:128)
at java.base/java.util.ArrayList.forEach(ArrayList.java:1540)
at org.testng.TestRunner.privateRun(TestRunner.java:767)
at org.testng.TestRunner.run(TestRunner.java:588)
at org.testng.SuiteRunner.runTest(SuiteRunner.java:384)
at org.testng.SuiteRunner.access$000(SuiteRunner.java:28)
at org.testng.SuiteRunner$SuiteWorker.run(SuiteRunner.java:425)
at org.testng.internal.thread.ThreadUtil.lambda$execute$0(ThreadUtil.java:68)
at java.base/java.util.concurrent.FutureTask.run(FutureTask.java:264)
at java.base/java.util.concurrent.ThreadPoolExecutor.runWorker(ThreadPoolExecutor.java:1128)
at java.base/java.util.concurrent.ThreadPoolExecutor$Worker.run(ThreadPoolExecutor.java:628)
at java.base/java.lang.Thread.run(Thread.java:834)
]]>
            </full-stacktrace>
          </exception> <!-- java.lang.AssertionError -->
          <reporter-output>
          </reporter-output>
        </test-method> <!-- LoginTest -->
        <test-method signature="LoginTest(java.lang.String, java.lang.String)[pri:0, instance:com.inetbanking.testCases.TC_LoginTest_001@1c98290c]" started-at="2020-08-24T16:53:52 ICT" name="LoginTest" data-provider="getData" finished-at="2020-08-24T16:53:53 ICT" duration-ms="981" status="FAIL">
          <params>
            <param index="0">
              <value>
                <![CDATA[alex@email.com]]>
              </value>
            </param>
            <param index="1">
              <value>
                <![CDATA[seleniumpython321]]>
              </value>
            </param>
          </params>
          <exception class="java.lang.AssertionError">
            <message>
              <![CDATA[expected [Login | Salesforce3623] but found [Login | Salesforce]]]>
            </message>
            <full-stacktrace>
              <![CDATA[java.lang.AssertionError: expected [Login | Salesforce3623] but found [Login | Salesforce]
at org.testng.Assert.fail(Assert.java:97)
at org.testng.Assert.assertEqualsImpl(Assert.java:136)
at org.testng.Assert.assertEquals(Assert.java:118)
at org.testng.Assert.assertEquals(Assert.java:575)
at org.testng.Assert.assertEquals(Assert.java:585)
at com.inetbanking.testCases.TC_LoginTest_001.LoginTest(TC_LoginTest_001.java:32)
at java.base/jdk.internal.reflect.NativeMethodAccessorImpl.invoke0(Native Method)
at java.base/jdk.internal.reflect.NativeMethodAccessorImpl.invoke(NativeMethodAccessorImpl.java:62)
at java.base/jdk.internal.reflect.DelegatingMethodAccessorImpl.invoke(DelegatingMethodAccessorImpl.java:43)
at java.base/java.lang.reflect.Method.invoke(Method.java:566)
at org.testng.internal.MethodInvocationHelper.invokeMethod(MethodInvocationHelper.java:135)
at org.testng.internal.TestInvoker.invokeMethod(TestInvoker.java:598)
at org.testng.internal.TestInvoker.invokeTestMethod(TestInvoker.java:174)
at org.testng.internal.MethodRunner.runInSequence(MethodRunner.java:46)
at org.testng.internal.TestInvoker$MethodInvocationAgent.invoke(TestInvoker.java:821)
at org.testng.internal.TestInvoker.invokeTestMethods(TestInvoker.java:147)
at org.testng.internal.TestMethodWorker.invokeTestMethods(TestMethodWorker.java:146)
at org.testng.internal.TestMethodWorker.run(TestMethodWorker.java:128)
at java.base/java.util.ArrayList.forEach(ArrayList.java:1540)
at org.testng.TestRunner.privateRun(TestRunner.java:767)
at org.testng.TestRunner.run(TestRunner.java:588)
at org.testng.SuiteRunner.runTest(SuiteRunner.java:384)
at org.testng.SuiteRunner.access$000(SuiteRunner.java:28)
at org.testng.SuiteRunner$SuiteWorker.run(SuiteRunner.java:425)
at org.testng.internal.thread.ThreadUtil.lambda$execute$0(ThreadUtil.java:68)
at java.base/java.util.concurrent.FutureTask.run(FutureTask.java:264)
at java.base/java.util.concurrent.ThreadPoolExecutor.runWorker(ThreadPoolExecutor.java:1128)
at java.base/java.util.concurrent.ThreadPoolExecutor$Worker.run(ThreadPoolExecutor.java:628)
at java.base/java.lang.Thread.run(Thread.java:834)
]]>
            </full-stacktrace>
          </exception> <!-- java.lang.AssertionError -->
          <reporter-output>
          </reporter-output>
        </test-method> <!-- LoginTest -->
        <test-method signature="LoginTest(java.lang.String, java.lang.String)[pri:0, instance:com.inetbanking.testCases.TC_LoginTest_001@1c98290c]" started-at="2020-08-24T16:53:53 ICT" name="LoginTest" data-provider="getData" finished-at="2020-08-24T16:53:54 ICT" duration-ms="888" status="FAIL">
          <params>
            <param index="0">
              <value>
                <![CDATA[ali@email.com]]>
              </value>
            </param>
            <param index="1">
              <value>
                <![CDATA[seleniumc##423]]>
              </value>
            </param>
          </params>
          <exception class="java.lang.AssertionError">
            <message>
              <![CDATA[expected [Login | Salesforce3623] but found [Login | Salesforce]]]>
            </message>
            <full-stacktrace>
              <![CDATA[java.lang.AssertionError: expected [Login | Salesforce3623] but found [Login | Salesforce]
at org.testng.Assert.fail(Assert.java:97)
at org.testng.Assert.assertEqualsImpl(Assert.java:136)
at org.testng.Assert.assertEquals(Assert.java:118)
at org.testng.Assert.assertEquals(Assert.java:575)
at org.testng.Assert.assertEquals(Assert.java:585)
at com.inetbanking.testCases.TC_LoginTest_001.LoginTest(TC_LoginTest_001.java:32)
at java.base/jdk.internal.reflect.NativeMethodAccessorImpl.invoke0(Native Method)
at java.base/jdk.internal.reflect.NativeMethodAccessorImpl.invoke(NativeMethodAccessorImpl.java:62)
at java.base/jdk.internal.reflect.DelegatingMethodAccessorImpl.invoke(DelegatingMethodAccessorImpl.java:43)
at java.base/java.lang.reflect.Method.invoke(Method.java:566)
at org.testng.internal.MethodInvocationHelper.invokeMethod(MethodInvocationHelper.java:135)
at org.testng.internal.TestInvoker.invokeMethod(TestInvoker.java:598)
at org.testng.internal.TestInvoker.invokeTestMethod(TestInvoker.java:174)
at org.testng.internal.MethodRunner.runInSequence(MethodRunner.java:46)
at org.testng.internal.TestInvoker$MethodInvocationAgent.invoke(TestInvoker.java:821)
at org.testng.internal.TestInvoker.invokeTestMethods(TestInvoker.java:147)
at org.testng.internal.TestMethodWorker.invokeTestMethods(TestMethodWorker.java:146)
at org.testng.internal.TestMethodWorker.run(TestMethodWorker.java:128)
at java.base/java.util.ArrayList.forEach(ArrayList.java:1540)
at org.testng.TestRunner.privateRun(TestRunner.java:767)
at org.testng.TestRunner.run(TestRunner.java:588)
at org.testng.SuiteRunner.runTest(SuiteRunner.java:384)
at org.testng.SuiteRunner.access$000(SuiteRunner.java:28)
at org.testng.SuiteRunner$SuiteWorker.run(SuiteRunner.java:425)
at org.testng.internal.thread.ThreadUtil.lambda$execute$0(ThreadUtil.java:68)
at java.base/java.util.concurrent.FutureTask.run(FutureTask.java:264)
at java.base/java.util.concurrent.ThreadPoolExecutor.runWorker(ThreadPoolExecutor.java:1128)
at java.base/java.util.concurrent.ThreadPoolExecutor$Worker.run(ThreadPoolExecutor.java:628)
at java.base/java.lang.Thread.run(Thread.java:834)
]]>
            </full-stacktrace>
          </exception> <!-- java.lang.AssertionError -->
          <reporter-output>
          </reporter-output>
        </test-method> <!-- LoginTest -->
        <test-method signature="closing()[pri:0, instance:com.inetbanking.testCases.TC_LoginTest_001@1c98290c]" started-at="2020-08-24T16:53:54 ICT" name="closing" finished-at="2020-08-24T16:53:55 ICT" duration-ms="1204" status="PASS">
          <reporter-output>
          </reporter-output>
        </test-method> <!-- closing -->
      </class> <!-- com.inetbanking.testCases.TC_LoginTest_001 -->
    </test> <!-- TestBanking App -->
  </suite> <!-- Suite -->
</testng-results>
